Workbook
Name Slicer_Location: #N/A
Name Slicer_Location1: #N/A

Sheet Raw Data
A1: Name | B1: Email | C1: Phone | D1: Location | E1: Date of Purchase | F1: Product | G1: Quantity | H1: Price | I1: Amount
A2: EMEKA SANNI | B2: emeka.sanni41@outlook.com | C2: 08452984153 | D2: IBADAN | E2: 2024-01-19 | F2: WRIST WATCH | G2: 4 | H2: 35000 | I2: =H2*G2 -> 140000
A3: blessing adekunle | B3: blessing.adekunle@yahoo.com | C3: 0446-049-5660 | D3: port harcourt | E3: 10/05/2024 | F3: SMARTPHONE | G3: 5 | H3: 250000 | I3: =H3*G3 -> 1250000
A4: musa chukwu | B4: musa.chukwu@yahoo.com | C4: 04634786122 | D4: KANO | E4: 17/02/2024 | F4: HANDBAG | G4: 3 | H4: 5000 | I4: =H4*G4 -> 15000
A5: CHUKWUDI OKORO | B5: chukwudi.okoro@gmail.com | D5: Kano | E5: 27/03/2024 | F5: HANDBAG | G5: 5 | H5: 5000 | I5: =H5*G5 -> 25000
A6: NGOZI IBRAHIM | B6: NGOZI.IBRAHIM@YAHOO.COM | C6: 0889-148-6546 | D6: KANO | E6: 2024-02-28 | F6: Smartphone | G6: 3 | H6: 250000 | I6: =H6*G6 -> 750000
A7: wale okoro | B7: wale.okoro@yahoo.com | D7: ENUGU | E7: 02/06/2024 | F7: Blender | G7: 5 | H7: 10000 | I7: =H7*G7 -> 50000
A8: ADAEZE ABUBAKAR | B8: adaeze.abubakar@outlook.com | C8: 0053-446-8826 | D8: Enugu | E8: 2024-02-07 | F8: smartphone | G8: 1 | H8: 250000 | I8: =H8*G8 -> 250000
A9: chinedu balogun | C9: 06199582254 | D9: abuja | E9: 2024-05-13 | F9: Blender | G9: 1 | H9: 10000 | I9: =H9*G9 -> 10000
A10: AISHA BALOGUN | B10: aisha.balogun@outlook.com | C10: 0051-697-8464 | D10: ibadan | E10: 2024-01-04 | F10: SMARTPHONE | G10: 1 | H10: 250000 | I10: =H10*G10 -> 250000
A11: IBRAHIM ABUBAKAR | B11: IBRAHIM.ABUBAKAR@GMAIL.COM | C11: 09139099603 | D11: Abuja | E11: 2024-05-13 | F11: Headphones | G11: 2 | H11: 70000 | I11: =H11*G11 -> 140000
A12: KUNLE OBI | B12: kunle.obi@gmail.com | D12: lagos | E12: 12/02/2024 | F12: Blender | G12: 2 | H12: 10000 | I12: =H12*G12 -> 20000
A13: Bisi Sanni | B13: bisi.sanni@yahoo.com | D13: Ibadan | E13: 28/04/2024 | F13: Blender | G13: 2 | H13: 10000 | I13: =H13*G13 -> 20000
A14: emeka okafor | B14: EMEKA.OKAFOR@GMAIL.COM | C14: 0776-467-2720 | D14: ENUGU | E14: 17/06/2024 | F14: Wrist Watch | G14: 1 | H14: 35000 | I14: =H14*G14 -> 35000
A15: abdullahi chukwu | B15: abdullahi.chukwu@yahoo.com | C15: 0352-056-1748 | D15: abuja | E15: 2024-05-19 | F15: wrist watch | G15: 1 | H15: 35000 | I15: =H15*G15 -> 35000
A16: toyin nwosu | B16: TOYIN.NWOSU@GMAIL.COM | C16: 0718-818-1741 | D16: abuja | E16: 2024-06-26 | F16: television | G16: 3 | H16: 300000 | I16: =H16*G16 -> 900000
A17: Halima Adeyemi | B17: HALIMA.ADEYEMI@OUTLOOK.COM | D17: Ibadan | E17: 2024-05-09 | F17: SNEAKERS | G17: 3 | H17: 40000 | I17: =H17*G17 -> 120000
A18: BUKOLA UMEH | B18: bukola.umeh@yahoo.com | C18: 07628331258 | D18: ABUJA | E18: 10/01/2024 | F18: Television | G18: 1 | H18: 300000 | I18: =H18*G18 -> 300000
A19: CHIDINMA BALOGUN | C19: 0865-797-5432 | D19: ABUJA | E19: 09/06/2024 | F19: Headphones | G19: 3 | H19: 70000 | I19: =H19*G19 -> 210000
A20: Chidinma Okafor | B20: chidinma.okafor@outlook.com | C20: 03100251678 | D20: lagos | E20: 14/01/2024 | F20: headphones | G20: 3 | H20: 70000 | I20: =H20*G20 -> 210000
A21: SANI OKAFOR | B21: sani.okafor@gmail.com | C21: 09022279180 | D21: Kano | E21: 11/05/2024 | F21: Smartphone | G21: 1 | H21: 250000 | I21: =H21*G21 -> 250000
A22: sani abubakar | B22: sani.abubakar78@outlook.com | C22: 0620-191-3274 | D22: Abuja | E22: 2024-05-22 | F22: Handbag | G22: 7 | H22: 5000 | I22: =H22*G22 -> 35000
A23: precious nwosu | B23: precious.nwosu@gmail.com | C23: 07010737504 | D23: lagos | E23: 2024-05-28 | F23: HEADPHONES | G23: 4 | H23: 70000 | I23: =H23*G23 -> 280000
A24: halima nwachukwu | B24: HALIMA.NWACHUKWU@YAHOO.COM | C24: 0777-412-1547 | D24: ABUJA | E24: 18/01/2024 | F24: Sneakers | G24: 4 | H24: 40000 | I24: =H24*G24 -> 160000
A25: RUKAYAT ADEYEMI | B25: rukayat.adeyemi@gmail.com | C25: 0309-260-0267 | E25: 24/05/2024 | F25: Sneakers | G25: 1 | H25: 40000 | I25: =H25*G25 -> 40000
A26: Aisha Umeh | B26: AISHA.UMEH@GMAIL.COM | C26: 06133310014 | D26: Abuja | E26: 18/01/2024 | F26: Laptop | G26: 3 | H26: 350000 | I26: =H26*G26 -> 1050000
A27: Obinna Nwosu | B27: OBINNA.NWOSU@OUTLOOK.COM | C27: 02650201462 | D27: Enugu | E27: 11/05/2024 | F27: blender | G27: 4 | H27: 10000 | I27: =H27*G27 -> 40000
A28: CHIAMAKA SANNI | B28: chiamaka.sanni@yahoo.com | C28: 0738-344-9223 | D28: Kano | E28: 08/01/2024 | F28: WRIST WATCH | G28: 1 | H28: 35000 | I28: =H28*G28 -> 35000
A29: Chukwudi Obi | B29: chukwudi.obi@outlook.com | C29: 0075-116-3726 | D29: Port Harcourt | E29: 26/05/2024 | F29: laptop | G29: 3 | H29: 350000 | I29: =H29*G29 -> 1050000
A30: funke suleiman | B30: funke.suleiman@outlook.com | C30: 09059582785 | E30: 2024-06-14 | F30: laptop | G30: 1 | H30: 350000 | I30: =H30*G30 -> 350000
A31: segun obi | B31: SEGUN.OBI@YAHOO.COM | C31: 0724-920-8682 | D31: kano | E31: 15/06/2024 | F31: smartphone | G31: 5 | H31: 250000 | I31: =H31*G31 -> 1250000
A32: kelechi obi | B32: kelechi.obi@yahoo.com | C32: 09873200080 | D32: abuja | E32: 15/06/2024 | F32: blender | G32: 5 | H32: 10000 | I32: =H32*G32 -> 50000
A33: Ibrahim Sanni | B33: IBRAHIM.SANNI@OUTLOOK.COM | C33: 0620-579-8682 | D33: kano | E33: 2024-05-15 | F33: wrist watch | G33: 4 | H33: 35000 | I33: =H33*G33 -> 140000
A34: Chiamaka Yusuf | C34: 0332-493-5164 | D34: Kano | E34: 15/01/2024 | F34: Wrist Watch | G34: 5 | H34: 35000 | I34: =H34*G34 -> 175000
A35: Wale Chukwu | B35: wale.chukwu@outlook.com | C35: 0983-478-8783 | D35: PORT HARCOURT | E35: 26/01/2024 | F35: LAPTOP | G35: 4 | H35: 350000 | I35: =H35*G35 -> 1400000
A36: Funke Obi | B36: funke.obi@gmail.com | D36: Abuja | E36: 25/06/2024 | F36: Wrist Watch | G36: 4 | H36: 35000 | I36: =H36*G36 -> 140000
A37: Chiamaka Yusuf | C37: 0332-493-5164 | D37: Kano | E37: 15/01/2024 | F37: Wrist Watch | G37: 5 | H37: 35000 | I37: =H37*G37 -> 175000
A38: Abdullahi Yusuf | B38: ABDULLAHI.YUSUF@GMAIL.COM | C38: 0616-751-3613 | D38: lagos | E38: 08/06/2024 | F38: BLENDER | G38: 2 | H38: 10000 | I38: =H38*G38 -> 20000
A39: CHIAMAKA AFOLABI | B39: chiamaka.afolabi9@yahoo.com | C39: 0859-952-8907 | E39: 2024-05-05 | F39: Handbag | G39: 3 | H39: 5000 | I39: =H39*G39 -> 15000
A40: FATIMA ABUBAKAR | B40: fatima.abubakar@yahoo.com | C40: 03287046557 | D40: LAGOS | E40: 16/04/2024 | F40: Television | G40: 1 | H40: 300000 | I40: =H40*G40 -> 300000
...

Sheet Cleaned Data
A1: Name | B1: Email | C1: Phone | D1: Location | E1: Date of Purchase | F1: Product | G1: Quantity | H1: Price | I1: Amount
A2: =PROPER(TRIM('Raw Data'!A2)) -> Emeka Sanni | B2: =IF('Raw Data'!B2="","Missing",LOWER(TRIM('Raw Data'!B2))) -> emeka.sanni41@outlook.com | C2: =IF('Raw Data'!C2="","Missing",TRIM('Raw Data'!C2)) -> 08452984153 | D2: =IF('Raw Data'!D2="","Missing",PROPER(TRIM('Raw Data'!D2))) -> Ibadan | E2: =IF(ISNUMBER(SEARCH("/",'Raw Data'!E2)),DATE(VALUE(RIGHT('Raw Data'!E2,4)),VALUE(MID('Raw Data'!E2,4,2)),VALUE(LEFT('Raw Data'!E2,2))),DATE(VALUE(LEFT('Raw Data'!E2,4)),VALUE(MID('Raw Data'!E2,6,2)),VALUE(RIGHT('Raw Data'!E2,2)))) -> 45310 | F2: =PROPER('Raw Data'!F2) -> Wrist Watch | G2: 4 | H2: 35000 | I2: =G2*H2 -> 140000
A3: =PROPER(TRIM('Raw Data'!A3)) -> Blessing Adekunle | B3: =IF('Raw Data'!B3="","Missing",LOWER(TRIM('Raw Data'!B3))) -> blessing.adekunle@yahoo.com | C3: =IF('Raw Data'!C3="","Missing",TRIM('Raw Data'!C3)) -> 0446-049-5660 | D3: =IF('Raw Data'!D3="","Missing",PROPER(TRIM('Raw Data'!D3))) -> Port Harcourt | E3: =IF(ISNUMBER(SEARCH("/",'Raw Data'!E3)),DATE(VALUE(RIGHT('Raw Data'!E3,4)),VALUE(MID('Raw Data'!E3,4,2)),VALUE(LEFT('Raw Data'!E3,2))),DATE(VALUE(LEFT('Raw Data'!E3,4)),VALUE(MID('Raw Data'!E3,6,2)),VALUE(RIGHT('Raw Data'!E3,2)))) -> 45422 | F3: =PROPER('Raw Data'!F3) -> Smartphone | G3: 5 | H3: 250000 | I3: =G3*H3 -> 1250000
A4: =PROPER(TRIM('Raw Data'!A4)) -> Musa Chukwu | B4: =IF('Raw Data'!B4="","Missing",LOWER(TRIM('Raw Data'!B4))) -> musa.chukwu@yahoo.com | C4: =IF('Raw Data'!C4="","Missing",TRIM('Raw Data'!C4)) -> 04634786122 | D4: =IF('Raw Data'!D4="","Missing",PROPER(TRIM('Raw Data'!D4))) -> Kano | E4: =IF(ISNUMBER(SEARCH("/",'Raw Data'!E4)),DATE(VALUE(RIGHT('Raw Data'!E4,4)),VALUE(MID('Raw Data'!E4,4,2)),VALUE(LEFT('Raw Data'!E4,2))),DATE(VALUE(LEFT('Raw Data'!E4,4)),VALUE(MID('Raw Data'!E4,6,2)),VALUE(RIGHT('Raw Data'!E4,2)))) -> 45339 | F4: =PROPER('Raw Data'!F4) -> Handbag | G4: 3 | H4: 5000 | I4: =G4*H4 -> 15000
A5: =PROPER(TRIM('Raw Data'!A5)) -> Chukwudi Okoro | B5: =IF('Raw Data'!B5="","Missing",LOWER(TRIM('Raw Data'!B5))) -> chukwudi.okoro@gmail.com | C5: =IF('Raw Data'!C5="","Missing",TRIM('Raw Data'!C5)) -> Missing | D5: =IF('Raw Data'!D5="","Missing",PROPER(TRIM('Raw Data'!D5))) -> Kano | E5: =IF(ISNUMBER(SEARCH("/",'Raw Data'!E5)),DATE(VALUE(RIGHT('Raw Data'!E5,4)),VALUE(MID('Raw Data'!E5,4,2)),VALUE(LEFT('Raw Data'!E5,2))),DATE(VALUE(LEFT('Raw Data'!E5,4)),VALUE(MID('Raw Data'!E5,6,2)),VALUE(RIGHT('Raw Data'!E5,2)))) -> 45378 | F5: =PROPER('Raw Data'!F5) -> Handbag | G5: 5 | H5: 5000 | I5: =G5*H5 -> 25000
A6: =PROPER(TRIM('Raw Data'!A6)) -> Ngozi Ibrahim | B6: =IF('Raw Data'!B6="","Missing",LOWER(TRIM('Raw Data'!B6))) -> ngozi.ibrahim@yahoo.com | C6: =IF('Raw Data'!C6="","Missing",TRIM('Raw Data'!C6)) -> 0889-148-6546 | D6: =IF('Raw Data'!D6="","Missing",PROPER(TRIM('Raw Data'!D6))) -> Kano | E6: =IF(ISNUMBER(SEARCH("/",'Raw Data'!E6)),DATE(VALUE(RIGHT('Raw Data'!E6,4)),VALUE(MID('Raw Data'!E6,4,2)),VALUE(LEFT('Raw Data'!E6,2))),DATE(VALUE(LEFT('Raw Data'!E6,4)),VALUE(MID('Raw Data'!E6,6,2)),VALUE(RIGHT('Raw Data'!E6,2)))) -> 45350 | F6: =PROPER('Raw Data'!F6) -> Smartphone | G6: 3 | H6: 250000 | I6: =G6*H6 -> 750000
A7: =PROPER(TRIM('Raw Data'!A7)) -> Wale Okoro | B7: =IF('Raw Data'!B7="","Missing",LOWER(TRIM('Raw Data'!B7))) -> wale.okoro@yahoo.com | C7: =IF('Raw Data'!C7="","Missing",TRIM('Raw Data'!C7)) -> Missing | D7: =IF('Raw Data'!D7="","Missing",PROPER(TRIM('Raw Data'!D7))) -> Enugu | E7: =IF(ISNUMBER(SEARCH("/",'Raw Data'!E7)),DATE(VALUE(RIGHT('Raw Data'!E7,4)),VALUE(MID('Raw Data'!E7,4,2)),VALUE(LEFT('Raw Data'!E7,2))),DATE(VALUE(LEFT('Raw Data'!E7,4)),VALUE(MID('Raw Data'!E7,6,2)),VALUE(RIGHT('Raw Data'!E7,2)))) -> 45445 | F7: =PROPER('Raw Data'!F7) -> Blender | G7: 5 | H7: 10000 | I7: =G7*H7 -> 50000
A8: =PROPER(TRIM('Raw Data'!A8)) -> Adaeze Abubakar | B8: =IF('Raw Data'!B8="","Missing",LOWER(TRIM('Raw Data'!B8))) -> adaeze.abubakar@outlook.com | C8: =IF('Raw Data'!C8="","Missing",TRIM('Raw Data'!C8)) -> 0053-446-8826 | D8: =IF('Raw Data'!D8="","Missing",PROPER(TRIM('Raw Data'!D8))) -> Enugu | E8: =IF(ISNUMBER(SEARCH("/",'Raw Data'!E8)),DATE(VALUE(RIGHT('Raw Data'!E8,4)),VALUE(MID('Raw Data'!E8,4,2)),VALUE(LEFT('Raw Data'!E8,2))),DATE(VALUE(LEFT('Raw Data'!E8,4)),VALUE(MID('Raw Data'!E8,6,2)),VALUE(RIGHT('Raw Data'!E8,2)))) -> 45329 | F8: =PROPER('Raw Data'!F8) -> Smartphone | G8: 1 | H8: 250000 | I8: =G8*H8 -> 250000
A9: =PROPER(TRIM('Raw Data'!A9)) -> Chinedu Balogun | B9: =IF('Raw Data'!B9="","Missing",LOWER(TRIM('Raw Data'!B9))) -> Missing | C9: =IF('Raw Data'!C9="","Missing",TRIM('Raw Data'!C9)) -> 06199582254 | D9: =IF('Raw Data'!D9="","Missing",PROPER(TRIM('Raw Data'!D9))) -> Abuja | E9: =IF(ISNUMBER(SEARCH("/",'Raw Data'!E9)),DATE(VALUE(RIGHT('Raw Data'!E9,4)),VALUE(MID('Raw Data'!E9,4,2)),VALUE(LEFT('Raw Data'!E9,2))),DATE(VALUE(LEFT('Raw Data'!E9,4)),VALUE(MID('Raw Data'!E9,6,2)),VALUE(RIGHT('Raw Data'!E9,2)))) -> 45425 | F9: =PROPER('Raw Data'!F9) -> Blender | G9: 1 | H9: 10000 | I9: =G9*H9 -> 10000
A10: =PROPER(TRIM('Raw Data'!A10)) -> Aisha Balogun | B10: =IF('Raw Data'!B10="","Missing",LOWER(TRIM('Raw Data'!B10))) -> aisha.balogun@outlook.com | C10: =IF('Raw Data'!C10="","Missing",TRIM('Raw Data'!C10)) -> 0051-697-8464 | D10: =IF('Raw Data'!D10="","Missing",PROPER(TRIM('Raw Data'!D10))) -> Ibadan | E10: =IF(ISNUMBER(SEARCH("/",'Raw Data'!E10)),DATE(VALUE(RIGHT('Raw Data'!E10,4)),VALUE(MID('Raw Data'!E10,4,2)),VALUE(LEFT('Raw Data'!E10,2))),DATE(VALUE(LEFT('Raw Data'!E10,4)),VALUE(MID('Raw Data'!E10,6,2)),VALUE(RIGHT('Raw Data'!E10,2)))) -> 45295 | F10: =PROPER('Raw Data'!F10) -> Smartphone | G10: 1 | H10: 250000 | I10: =G10*H10 -> 250000
A11: =PROPER(TRIM('Raw Data'!A11)) -> Ibrahim Abubakar | B11: =IF('Raw Data'!B11="","Missing",LOWER(TRIM('Raw Data'!B11))) -> ibrahim.abubakar@gmail.com | C11: =IF('Raw Data'!C11="","Missing",TRIM('Raw Data'!C11)) -> 09139099603 | D11: =IF('Raw Data'!D11="","Missing",PROPER(TRIM('Raw Data'!D11))) -> Abuja | E11: =IF(ISNUMBER(SEARCH("/",'Raw Data'!E11)),DATE(VALUE(RIGHT('Raw Data'!E11,4)),VALUE(MID('Raw Data'!E11,4,2)),VALUE(LEFT('Raw Data'!E11,2))),DATE(VALUE(LEFT('Raw Data'!E11,4)),VALUE(MID('Raw Data'!E11,6,2)),VALUE(RIGHT('Raw Data'!E11,2)))) -> 45425 | F11: =PROPER('Raw Data'!F11) -> Headphones | G11: 2 | H11: 70000 | I11: =G11*H11 -> 140000
A12: =PROPER(TRIM('Raw Data'!A12)) -> Kunle Obi | B12: =IF('Raw Data'!B12="","Missing",LOWER(TRIM('Raw Data'!B12))) -> kunle.obi@gmail.com | C12: =IF('Raw Data'!C12="","Missing",TRIM('Raw Data'!C12)) -> Missing | D12: =IF('Raw Data'!D12="","Missing",PROPER(TRIM('Raw Data'!D12))) -> Lagos | E12: =IF(ISNUMBER(SEARCH("/",'Raw Data'!E12)),DATE(VALUE(RIGHT('Raw Data'!E12,4)),VALUE(MID('Raw Data'!E12,4,2)),VALUE(LEFT('Raw Data'!E12,2))),DATE(VALUE(LEFT('Raw Data'!E12,4)),VALUE(MID('Raw Data'!E12,6,2)),VALUE(RIGHT('Raw Data'!E12,2)))) -> 45334 | F12: =PROPER('Raw Data'!F12) -> Blender | G12: 2 | H12: 10000 | I12: =G12*H12 -> 20000
A13: =PROPER(TRIM('Raw Data'!A13)) -> Bisi Sanni | B13: =IF('Raw Data'!B13="","Missing",LOWER(TRIM('Raw Data'!B13))) -> bisi.sanni@yahoo.com | C13: =IF('Raw Data'!C13="","Missing",TRIM('Raw Data'!C13)) -> Missing | D13: =IF('Raw Data'!D13="","Missing",PROPER(TRIM('Raw Data'!D13))) -> Ibadan | E13: =IF(ISNUMBER(SEARCH("/",'Raw Data'!E13)),DATE(VALUE(RIGHT('Raw Data'!E13,4)),VALUE(MID('Raw Data'!E13,4,2)),VALUE(LEFT('Raw Data'!E13,2))),DATE(VALUE(LEFT('Raw Data'!E13,4)),VALUE(MID('Raw Data'!E13,6,2)),VALUE(RIGHT('Raw Data'!E13,2)))) -> 45410 | F13: =PROPER('Raw Data'!F13) -> Blender | G13: 2 | H13: 10000 | I13: =G13*H13 -> 20000
... A36: =PROPER(TRIM('Raw Data'!A36)) -> Funke Obi | B36: =IF('Raw Data'!B36="","Missing",LOWER(TRIM('Raw Data'!B36))) -> funke.obi@gmail.com | C36: =IF('Raw Data'!C36="","Missing",TRIM('Raw Data'!C36)) -> Missing | D36: =IF('Raw Data'!D36="","Missing",PROPER(TRIM('Raw Data'!D36))) -> Abuja | E36: =IF(ISNUMBER(SEARCH("/",'Raw Data'!E36)),DATE(VALUE(RIGHT('Raw Data'!E36,4)),VALUE(MID('Raw Data'!E36,4,2)),VALUE(LEFT('Raw Data'!E36,2))),DATE(VALUE(LEFT('Raw Data'!E36,4)),VALUE(MID('Raw Data'!E36,6,2)),VALUE(RIGHT('Raw Data'!E36,2)))) -> 45468 | F36: =PROPER('Raw Data'!F36) -> Wrist Watch | G36: 4 | H36: 35000 | I36: =G36*H36 -> 140000
A37: =PROPER(TRIM('Raw Data'!A38)) -> Abdullahi Yusuf | B37: =IF('Raw Data'!B38="","Missing",LOWER(TRIM('Raw Data'!B38))) -> abdullahi.yusuf@gmail.com | C37: =IF('Raw Data'!C38="","Missing",TRIM('Raw Data'!C38)) -> 0616-751-3613 | D37: =IF('Raw Data'!D38="","Missing",PROPER(TRIM('Raw Data'!D38))) -> Lagos | E37: =IF(ISNUMBER(SEARCH("/",'Raw Data'!E37)),DATE(VALUE(RIGHT('Raw Data'!E37,4)),VALUE(MID('Raw Data'!E37,4,2)),VALUE(LEFT('Raw Data'!E37,2))),DATE(VALUE(LEFT('Raw Data'!E37,4)),VALUE(MID('Raw Data'!E37,6,2)),VALUE(RIGHT('Raw Data'!E37,2)))) -> 45306 | F37: =PROPER('Raw Data'!F38) -> Blender | G37: 2 | H37: 10000 | I37: =G37*H37 -> 20000
A38: =PROPER(TRIM('Raw Data'!A39)) -> Chiamaka Afolabi | B38: =IF('Raw Data'!B39="","Missing",LOWER(TRIM('Raw Data'!B39))) -> chiamaka.afolabi9@yahoo.com | C38: =IF('Raw Data'!C39="","Missing",TRIM('Raw Data'!C39)) -> 0859-952-8907 | D38: =IF('Raw Data'!D39="","Missing",PROPER(TRIM('Raw Data'!D39))) -> Missing | E38: =IF(ISNUMBER(SEARCH("/",'Raw Data'!E38)),DATE(VALUE(RIGHT('Raw Data'!E38,4)),VALUE(MID('Raw Data'!E38,4,2)),VALUE(LEFT('Raw Data'!E38,2))),DATE(VALUE(LEFT('Raw Data'!E38,4)),VALUE(MID('Raw Data'!E38,6,2)),VALUE(RIGHT('Raw Data'!E38,2)))) -> 45451 | F38: =PROPER('Raw Data'!F39) -> Handbag | G38: 3 | H38: 5000 | I38: =G38*H38 -> 15000
A39: =PROPER(TRIM('Raw Data'!A40)) -> Fatima Abubakar | B39: =IF('Raw Data'!B40="","Missing",LOWER(TRIM('Raw Data'!B40))) -> fatima.abubakar@yahoo.com | C39: =IF('Raw Data'!C40="","Missing",TRIM('Raw Data'!C40)) -> 03287046557 | D39: =IF('Raw Data'!D40="","Missing",PROPER(TRIM('Raw Data'!D40))) -> Lagos | E39: =IF(ISNUMBER(SEARCH("/",'Raw Data'!E39)),DATE(VALUE(RIGHT('Raw Data'!E39,4)),VALUE(MID('Raw Data'!E39,4,2)),VALUE(LEFT('Raw Data'!E39,2))),DATE(VALUE(LEFT('Raw Data'!E39,4)),VALUE(MID('Raw Data'!E39,6,2)),VALUE(RIGHT('Raw Data'!E39,2)))) -> 45417 | F39: =PROPER('Raw Data'!F40) -> Television | G39: 1 | H39: 300000 | I39: =G39*H39 -> 300000
A40: =PROPER(TRIM('Raw Data'!A41)) -> Zainab Yusuf | B40: =IF('Raw Data'!B41="","Missing",LOWER(TRIM('Raw Data'!B41))) -> zainab.yusuf@gmail.com | C40: =IF('Raw Data'!C41="","Missing",TRIM('Raw Data'!C41)) -> Missing | D40: =IF('Raw Data'!D41="","Missing",PROPER(TRIM('Raw Data'!D41))) -> Lagos | E40: =IF(ISNUMBER(SEARCH("/",'Raw Data'!E40)),DATE(VALUE(RIGHT('Raw Data'!E40,4)),VALUE(MID('Raw Data'!E40,4,2)),VALUE(LEFT('Raw Data'!E40,2))),DATE(VALUE(LEFT('Raw Data'!E40,4)),VALUE(MID('Raw Data'!E40,6,2)),VALUE(RIGHT('Raw Data'!E40,2)))) -> 45398 | F40: =PROPER('Raw Data'!F41) -> Television | G40: 4 | H40: 300000 | I40: =G40*H40 -> 1200000
A41: =PROPER(TRIM('Raw Data'!A42)) -> Chiamaka Sanni | B41: =IF('Raw Data'!B42="","Missing",LOWER(TRIM('Raw Data'!B42))) -> chiamaka.sanni@yahoo.com | C41: =IF('Raw Data'!C42="","Missing",TRIM('Raw Data'!C42)) -> 03372117815 | D41: =IF('Raw Data'!D42="","Missing",PROPER(TRIM('Raw Data'!D42))) -> Ibadan | E41: =IF(ISNUMBER(SEARCH("/",'Raw Data'!E41)),DATE(VALUE(RIGHT('Raw Data'!E41,4)),VALUE(MID('Raw Data'!E41,4,2)),VALUE(LEFT('Raw Data'!E41,2))),DATE(VALUE(LEFT('Raw Data'!E41,4)),VALUE(MID('Raw Data'!E41,6,2)),VALUE(RIGHT('Raw Data'!E41,2)))) -> 45438 | F41: =PROPER('Raw Data'!F42) -> Smartphone | G41: 3 | H41: 250000 | I41: =G41*H41 -> 750000
A42: =PROPER(TRIM('Raw Data'!A44)) -> Segun Ibrahim | B42: =IF('Raw Data'!B44="","Missing",LOWER(TRIM('Raw Data'!B44))) -> segun.ibrahim@gmail.com | C42: =IF('Raw Data'!C44="","Missing",TRIM('Raw Data'!C44)) -> 07316723268 | D42: =IF('Raw Data'!D44="","Missing",PROPER(TRIM('Raw Data'!D44))) -> Ibadan | E42: =IF(ISNUMBER(SEARCH("/",'Raw Data'!E42)),DATE(VALUE(RIGHT('Raw Data'!E42,4)),VALUE(MID('Raw Data'!E42,4,2)),VALUE(LEFT('Raw Data'!E42,2))),DATE(VALUE(LEFT('Raw Data'!E42,4)),VALUE(MID('Raw Data'!E42,6,2)),VALUE(RIGHT('Raw Data'!E42,2)))) -> 45303 | F42: =PROPER('Raw Data'!F44) -> Laptop | G42: 2 | H42: 350000 | I42: =G42*H42 -> 700000
A43: =PROPER(TRIM('Raw Data'!A45)) -> Wale Yusuf | B43: =IF('Raw Data'!B45="","Missing",LOWER(TRIM('Raw Data'!B45))) -> wale.yusuf@outlook.com | C43: =IF('Raw Data'!C45="","Missing",TRIM('Raw Data'!C45)) -> 0706-360-6071 | D43: =IF('Raw Data'!D45="","Missing",PROPER(TRIM('Raw Data'!D45))) -> Lagos | E43: =IF(ISNUMBER(SEARCH("/",'Raw Data'!E43)),DATE(VALUE(RIGHT('Raw Data'!E43,4)),VALUE(MID('Raw Data'!E43,4,2)),VALUE(LEFT('Raw Data'!E43,2))),DATE(VALUE(LEFT('Raw Data'!E43,4)),VALUE(MID('Raw Data'!E43,6,2)),VALUE(RIGHT('Raw Data'!E43,2)))) -> 45350 | F43: =PROPER('Raw Data'!F45) -> Headphones | G43: 1 | H43: 70000 | I43: =G43*H43 -> 70000
A44: =PROPER(TRIM('Raw Data'!A46)) -> Fatima Umeh | B44: =IF('Raw Data'!B46="","Missing",LOWER(TRIM('Raw Data'!B46))) -> fatima.umeh@gmail.com | C44: =IF('Raw Data'!C46="","Missing",TRIM('Raw Data'!C46)) -> 0704-718-7463 | D44: =IF('Raw Data'!D46="","Missing",PROPER(TRIM('Raw Data'!D46))) -> Abuja | E44: =IF(ISNUMBER(SEARCH("/",'Raw Data'!E44)),DATE(VALUE(RIGHT('Raw Data'!E44,4)),VALUE(MID('Raw Data'!E44,4,2)),VALUE(LEFT('Raw Data'!E44,2))),DATE(VALUE(LEFT('Raw Data'!E44,4)),VALUE(MID('Raw Data'!E44,6,2)),VALUE(RIGHT('Raw Data'!E44,2)))) -> 45378 | F44: =PROPER('Raw Data'!F46) -> Wrist Watch | G44: 5 | H44: 35000 | I44: =G44*H44 -> 175000
A45: =PROPER(TRIM('Raw Data'!A47)) -> Segun Ibrahim | B45: =IF('Raw Data'!B47="","Missing",LOWER(TRIM('Raw Data'!B47))) -> segun.ibrahim@gmail.com | C45: =IF('Raw Data'!C47="","Missing",TRIM('Raw Data'!C47)) -> 0732-904-8449 | D45: =IF('Raw Data'!D47="","Missing",PROPER(TRIM('Raw Data'!D47))) -> Port Harcourt | E45: =IF(ISNUMBER(SEARCH("/",'Raw Data'!E45)),DATE(VALUE(RIGHT('Raw Data'!E45,4)),VALUE(MID('Raw Data'!E45,4,2)),VALUE(LEFT('Raw Data'!E45,2))),DATE(VALUE(LEFT('Raw Data'!E45,4)),VALUE(MID('Raw Data'!E45,6,2)),VALUE(RIGHT('Raw Data'!E45,2)))) -> 45399 | F45: =PROPER('Raw Data'!F47) -> Wrist Watch | G45: 4 | H45: 35000 | I45: =G45*H45 -> 140000
A46: =PROPER(TRIM('Raw Data'!A48)) -> Precious Okafor | B46: =IF('Raw Data'!B48="","Missing",LOWER(TRIM('Raw Data'!B48))) -> precious.okafor@outlook.com | C46: =IF('Raw Data'!C48="","Missing",TRIM('Raw Data'!C48)) -> Missing | D46: =IF('Raw Data'!D48="","Missing",PROPER(TRIM('Raw Data'!D48))) -> Port Harcourt | E46: =IF(ISNUMBER(SEARCH("/",'Raw Data'!E46)),DATE(VALUE(RIGHT('Raw Data'!E46,4)),VALUE(MID('Raw Data'!E46,4,2)),VALUE(LEFT('Raw Data'!E46,2))),DATE(VALUE(LEFT('Raw Data'!E46,4)),VALUE(MID('Raw Data'!E46,6,2)),VALUE(RIGHT('Raw Data'!E46,2)))) -> 45343 | F46: =PROPER('Raw Data'!F48) -> Laptop | G46: 3 | H46: 350000 | I46: =G46*H46 -> 1050000
A47: =PROPER(TRIM('Raw Data'!A49)) -> Ngozi Yusuf | B47: =IF('Raw Data'!B49="","Missing",LOWER(TRIM('Raw Data'!B49))) -> ngozi.yusuf@gmail.com | C47: =IF('Raw Data'!C49="","Missing",TRIM('Raw Data'!C49)) -> 0366-712-7684 | D47: =IF('Raw Data'!D49="","Missing",PROPER(TRIM('Raw Data'!D49))) -> Missing | E47: =IF(ISNUMBER(SEARCH("/",'Raw Data'!E47)),DATE(VALUE(RIGHT('Raw Data'!E47,4)),VALUE(MID('Raw Data'!E47,4,2)),VALUE(LEFT('Raw Data'!E47,2))),DATE(VALUE(LEFT('Raw Data'!E47,4)),VALUE(MID('Raw Data'!E47,6,2)),VALUE(RIGHT('Raw Data'!E47,2)))) -> 45423 | F47: =PROPER('Raw Data'!F49) -> Smartphone | G47: 2 | H47: 250000 | I47: =G47*H47 -> 500000
A48: =PROPER(TRIM('Raw Data'!A50)) -> Amaka Bello | B48: =IF('Raw Data'!B50="","Missing",LOWER(TRIM('Raw Data'!B50))) -> amaka.bello@gmail.com | C48: =IF('Raw Data'!C50="","Missing",TRIM('Raw Data'!C50)) -> 09575513137 | D48: =IF('Raw Data'!D50="","Missing",PROPER(TRIM('Raw Data'!D50))) -> Abuja | E48: =IF(ISNUMBER(SEARCH("/",'Raw Data'!E48)),DATE(VALUE(RIGHT('Raw Data'!E48,4)),VALUE(MID('Raw Data'!E48,4,2)),VALUE(LEFT('Raw Data'!E48,2))),DATE(VALUE(LEFT('Raw Data'!E48,4)),VALUE(MID('Raw Data'!E48,6,2)),VALUE(RIGHT('Raw Data'!E48,2)))) -> 45315 | F48: =PROPER('Raw Data'!F50) -> Blender | G48: 5 | H48: 10000 | I48: =G48*H48 -> 50000
A49: =PROPER(TRIM('Raw Data'!A51)) -> Sani Okafor | B49: =IF('Raw Data'!B51="","Missing",LOWER(TRIM('Raw Data'!B51))) -> sani.okafor34@gmail.com | C49: =IF('Raw Data'!C51="","Missing",TRIM('Raw Data'!C51)) -> 0269-060-4431 | D49: =IF('Raw Data'!D51="","Missing",PROPER(TRIM('Raw Data'!D51))) -> Kano | E49: =IF(ISNUMBER(SEARCH("/",'Raw Data'!E49)),DATE(VALUE(RIGHT('Raw Data'!E49,4)),VALUE(MID('Raw Data'!E49,4,2)),VALUE(LEFT('Raw Data'!E49,2))),DATE(VALUE(LEFT('Raw Data'!E49,4)),VALUE(MID('Raw Data'!E49,6,2)),VALUE(RIGHT('Raw Data'!E49,2)))) -> 45464 | F49: =PROPER('Raw Data'!F51) -> Wrist Watch | G49: 5 | H49: 35000 | I49: =G49*H49 -> 175000
A50: =PROPER(TRIM('Raw Data'!A52)) -> Aisha Obi | B50: =IF('Raw Data'!B52="","Missing",LOWER(TRIM('Raw Data'!B52))) -> aisha.obi@outlook.com | C50: =IF('Raw Data'!C52="","Missing",TRIM('Raw Data'!C52)) -> 0315-827-9401 | D50: =IF('Raw Data'!D52="","Missing",PROPER(TRIM('Raw Data'!D52))) -> Enugu | E50: =IF(ISNUMBER(SEARCH("/",'Raw Data'!E50)),DATE(VALUE(RIGHT('Raw Data'!E50,4)),VALUE(MID('Raw Data'!E50,4,2)),VALUE(LEFT('Raw Data'!E50,2))),DATE(VALUE(LEFT('Raw Data'!E50,4)),VALUE(MID('Raw Data'!E50,6,2)),VALUE(RIGHT('Raw Data'!E50,2)))) -> 45349 | F50: =PROPER('Raw Data'!F52) -> Handbag | G50: 4 | H50: 5000 | I50: =G50*H50 -> 20000
A51: =PROPER(TRIM('Raw Data'!A53)) -> Emeka Eze | B51: =IF('Raw Data'!B53="","Missing",LOWER(TRIM('Raw Data'!B53))) -> emeka.eze@gmail.com | C51: =IF('Raw Data'!C53="","Missing",TRIM('Raw Data'!C53)) -> 01144024264 | D51: =IF('Raw Data'!D53="","Missing",PROPER(TRIM('Raw Data'!D53))) -> Kano | E51: =IF(ISNUMBER(SEARCH("/",'Raw Data'!E51)),DATE(VALUE(RIGHT('Raw Data'!E51,4)),VALUE(MID('Raw Data'!E51,4,2)),VALUE(LEFT('Raw Data'!E51,2))),DATE(VALUE(LEFT('Raw Data'!E51,4)),VALUE(MID('Raw Data'!E51,6,2)),VALUE(RIGHT('Raw Data'!E51,2)))) -> 45367 | F51: =PROPER('Raw Data'!F53) -> Sneakers | G51: 5 | H51: 40000 | I51: =G51*H51 -> 200000
A52: =PROPER(TRIM('Raw Data'!A54)) -> Emeka Bello | B52: =IF('Raw Data'!B54="","Missing",LOWER(TRIM('Raw Data'!B54))) -> emeka.bello@yahoo.com | C52: =IF('Raw Data'!C54="","Missing",TRIM('Raw Data'!C54)) -> 0058-649-2083 | D52: =IF('Raw Data'!D54="","Missing",PROPER(TRIM('Raw Data'!D54))) -> Missing | E52: =IF(ISNUMBER(SEARCH("/",'Raw Data'!E52)),DATE(VALUE(RIGHT('Raw Data'!E52,4)),VALUE(MID('Raw Data'!E52,4,2)),VALUE(LEFT('Raw Data'!E52,2))),DATE(VALUE(LEFT('Raw Data'!E52,4)),VALUE(MID('Raw Data'!E52,6,2)),VALUE(RIGHT('Raw Data'!E52,2)))) -> 45343 | F52: =PROPER('Raw Data'!F54) -> Smartphone | G52: 4 | H52: 250000 | I52: =G52*H52 -> 1000000
A53: =PROPER(TRIM('Raw Data'!A55)) -> Ngozi Bello | B53: =IF('Raw Data'!B55="","Missing",LOWER(TRIM('Raw Data'!B55))) -> ngozi.bello@outlook.com | C53: =IF('Raw Data'!C55="","Missing",TRIM('Raw Data'!C55)) -> 0423-468-5356 | D53: =IF('Raw Data'!D55="","Missing",PROPER(TRIM('Raw Data'!D55))) -> Enugu | E53: =IF(ISNUMBER(SEARCH("/",'Raw Data'!E53)),DATE(VALUE(RIGHT('Raw Data'!E53,4)),VALUE(MID('Raw Data'!E53,4,2)),VALUE(LEFT('Raw Data'!E53,2))),DATE(VALUE(LEFT('Raw Data'!E53,4)),VALUE(MID('Raw Data'!E53,6,2)),VALUE(RIGHT('Raw Data'!E53,2)))) -> 45370 | F53: =PROPER('Raw Data'!F55) -> Wrist Watch | G53: 4 | H53: 35000 | I53: =G53*H53 -> 140000
... A73: =PROPER(TRIM('Raw Data'!A75)) -> Chiamaka Yusuf | B73: =IF('Raw Data'!B75="","Missing",LOWER(TRIM('Raw Data'!B75))) -> chiamaka.yusuf@outlook.com | C73: =IF('Raw Data'!C75="","Missing",TRIM('Raw Data'!C75)) -> 05545904544 | D73: =IF('Raw Data'!D75="","Missing",PROPER(TRIM('Raw Data'!D75))) -> Kano | E73: =IF(ISNUMBER(SEARCH("/",'Raw Data'!E73)),DATE(VALUE(RIGHT('Raw Data'!E73,4)),VALUE(MID('Raw Data'!E73,4,2)),VALUE(LEFT('Raw Data'!E73,2))),DATE(VALUE(LEFT('Raw Data'!E73,4)),VALUE(MID('Raw Data'!E73,6,2)),VALUE(RIGHT('Raw Data'!E73,2)))) -> 45468 | F73: =PROPER('Raw Data'!F75) -> Blender | G73: 5 | H73: 10000 | I73: =G73*H73 -> 50000
A74: =PROPER(TRIM('Raw Data'!A77)) -> Uche Okonkwo | B74: =IF('Raw Data'!B77="","Missing",LOWER(TRIM('Raw Data'!B77))) -> uche.okonkwo@gmail.com | C74: =IF('Raw Data'!C77="","Missing",TRIM('Raw Data'!C77)) -> 0948-219-9351 | D74: =IF('Raw Data'!D77="","Missing",PROPER(TRIM('Raw Data'!D77))) -> Lagos | E74: =IF(ISNUMBER(SEARCH("/",'Raw Data'!E74)),DATE(VALUE(RIGHT('Raw Data'!E74,4)),VALUE(MID('Raw Data'!E74,4,2)),VALUE(LEFT('Raw Data'!E74,2))),DATE(VALUE(LEFT('Raw Data'!E74,4)),VALUE(MID('Raw Data'!E74,6,2)),VALUE(RIGHT('Raw Data'!E74,2)))) -> 45431 | F74: =PROPER('Raw Data'!F77) -> Handbag | G74: 4 | H74: 5000 | I74: =G74*H74 -> 20000
A75: =PROPER(TRIM('Raw Data'!A78)) -> Zainab Adeyemi | B75: =IF('Raw Data'!B78="","Missing",LOWER(TRIM('Raw Data'!B78))) -> zainab.adeyemi@yahoo.com | C75: =IF('Raw Data'!C78="","Missing",TRIM('Raw Data'!C78)) -> 05759183623 | D75: =IF('Raw Data'!D78="","Missing",PROPER(TRIM('Raw Data'!D78))) -> Enugu | E75: =IF(ISNUMBER(SEARCH("/",'Raw Data'!E75)),DATE(VALUE(RIGHT('Raw Data'!E75,4)),VALUE(MID('Raw Data'!E75,4,2)),VALUE(LEFT('Raw Data'!E75,2))),DATE(VALUE(LEFT('Raw Data'!E75,4)),VALUE(MID('Raw Data'!E75,6,2)),VALUE(RIGHT('Raw Data'!E75,2)))) -> 45350 | F75: =PROPER('Raw Data'!F78) -> Smartphone | G75: 5 | H75: 250000 | I75: =G75*H75 -> 1250000
A76: =PROPER(TRIM('Raw Data'!A80)) -> Femi Adeyemi | B76: =IF('Raw Data'!B80="","Missing",LOWER(TRIM('Raw Data'!B80))) -> femi.adeyemi@gmail.com | C76: =IF('Raw Data'!C80="","Missing",TRIM('Raw Data'!C80)) -> 01815908301 | D76: =IF('Raw Data'!D80="","Missing",PROPER(TRIM('Raw Data'!D80))) -> Lagos | E76: =IF(ISNUMBER(SEARCH("/",'Raw Data'!E76)),DATE(VALUE(RIGHT('Raw Data'!E76,4)),VALUE(MID('Raw Data'!E76,4,2)),VALUE(LEFT('Raw Data'!E76,2))),DATE(VALUE(LEFT('Raw Data'!E76,4)),VALUE(MID('Raw Data'!E76,6,2)),VALUE(RIGHT('Raw Data'!E76,2)))) -> 45348 | F76: =PROPER('Raw Data'!F80) -> Sneakers | G76: 3 | H76: 40000 | I76: =G76*H76 -> 120000
A77: =PROPER(TRIM('Raw Data'!A81)) -> Zainab Obi | B77: =IF('Raw Data'!B81="","Missing",LOWER(TRIM('Raw Data'!B81))) -> zainab.obi@gmail.com | C77: =IF('Raw Data'!C81="","Missing",TRIM('Raw Data'!C81)) -> 07074137484 | D77: =IF('Raw Data'!D81="","Missing",PROPER(TRIM('Raw Data'!D81))) -> Ibadan | E77: =IF(ISNUMBER(SEARCH("/",'Raw Data'!E77)),DATE(VALUE(RIGHT('Raw Data'!E77,4)),VALUE(MID('Raw Data'!E77,4,2)),VALUE(LEFT('Raw Data'!E77,2))),DATE(VALUE(LEFT('Raw Data'!E77,4)),VALUE(MID('Raw Data'!E77,6,2)),VALUE(RIGHT('Raw Data'!E77,2)))) -> 45329 | F77: =PROPER('Raw Data'!F81) -> Television | G77: 3 | H77: 300000 | I77: =G77*H77 -> 900000
A78: =PROPER(TRIM('Raw Data'!A82)) -> Nkechi Ibrahim | B78: =IF('Raw Data'!B82="","Missing",LOWER(TRIM('Raw Data'!B82))) -> nkechi.ibrahim@gmail.com | C78: =IF('Raw Data'!C82="","Missing",TRIM('Raw Data'!C82)) -> 05656304813 | D78: =IF('Raw Data'!D82="","Missing",PROPER(TRIM('Raw Data'!D82))) -> Abuja | E78: =IF(ISNUMBER(SEARCH("/",'Raw Data'!E78)),DATE(VALUE(RIGHT('Raw Data'!E78,4)),VALUE(MID('Raw Data'!E78,4,2)),VALUE(LEFT('Raw Data'!E78,2))),DATE(VALUE(LEFT('Raw Data'!E78,4)),VALUE(MID('Raw Data'!E78,6,2)),VALUE(RIGHT('Raw Data'!E78,2)))) -> 45458 | F78: =PROPER('Raw Data'!F82) -> Wrist Watch | G78: 2 | H78: 35000 | I78: =G78*H78 -> 70000
A79: =PROPER(TRIM('Raw Data'!A83)) -> Tobi Ibrahim | B79: =IF('Raw Data'!B83="","Missing",LOWER(TRIM('Raw Data'!B83))) -> tobi.ibrahim@yahoo.com | C79: =IF('Raw Data'!C83="","Missing",TRIM('Raw Data'!C83)) -> 0200-977-3797 | D79: =IF('Raw Data'!D83="","Missing",PROPER(TRIM('Raw Data'!D83))) -> Ibadan | E79: =IF(ISNUMBER(SEARCH("/",'Raw Data'!E79)),DATE(VALUE(RIGHT('Raw Data'!E79,4)),VALUE(MID('Raw Data'!E79,4,2)),VALUE(LEFT('Raw Data'!E79,2))),DATE(VALUE(LEFT('Raw Data'!E79,4)),VALUE(MID('Raw Data'!E79,6,2)),VALUE(RIGHT('Raw Data'!E79,2)))) -> 45421 | F79: =PROPER('Raw Data'!F83) -> Blender | G79: 4 | H79: 10000 | I79: =G79*H79 -> 40000
A80: =PROPER(TRIM('Raw Data'!A84)) -> Victor Okoro | B80: =IF('Raw Data'!B84="","Missing",LOWER(TRIM('Raw Data'!B84))) -> victor.okoro@gmail.com | C80: =IF('Raw Data'!C84="","Missing",TRIM('Raw Data'!C84)) -> 04078066717 | D80: =IF('Raw Data'!D84="","Missing",PROPER(TRIM('Raw Data'!D84))) -> Lagos | E80: =IF(ISNUMBER(SEARCH("/",'Raw Data'!E80)),DATE(VALUE(RIGHT('Raw Data'!E80,4)),VALUE(MID('Raw Data'!E80,4,2)),VALUE(LEFT('Raw Data'!E80,2))),DATE(VALUE(LEFT('Raw Data'!E80,4)),VALUE(MID('Raw Data'!E80,6,2)),VALUE(RIGHT('Raw Data'!E80,2)))) -> 45395 | F80: =PROPER('Raw Data'!F84) -> Headphones | G80: 4 | H80: 70000 | I80: =G80*H80 -> 280000
A81: =PROPER(TRIM('Raw Data'!A85)) -> Fatima Suleiman | B81: =IF('Raw Data'!B85="","Missing",LOWER(TRIM('Raw Data'!B85))) -> fatima.suleiman@yahoo.com | C81: =IF('Raw Data'!C85="","Missing",TRIM('Raw Data'!C85)) -> 0163-624-6770 | D81: =IF('Raw Data'!D85="","Missing",PROPER(TRIM('Raw Data'!D85))) -> Ibadan | E81: =IF(ISNUMBER(SEARCH("/",'Raw Data'!E81)),DATE(VALUE(RIGHT('Raw Data'!E81,4)),VALUE(MID('Raw Data'!E81,4,2)),VALUE(LEFT('Raw Data'!E81,2))),DATE(VALUE(LEFT('Raw Data'!E81,4)),VALUE(MID('Raw Data'!E81,6,2)),VALUE(RIGHT('Raw Data'!E81,2)))) -> 45433 | F81: =PROPER('Raw Data'!F85) -> Handbag | G81: 1 | H81: 5000 | I81: =G81*H81 -> 5000
...

Sheet Pivot Summary
A1: Pivot Summary
A2: Pivot Summary is linked to the Dashboard
A3: Product | B3: Count of Amount | G3: Row Labels | H3: Sum of Amount
A4: Blender | B4: 14 | G4: Jan | H4: 11620000
A5: Handbag | B5: 14 | G5: Feb | H5: 10175000
A6: Headphones | B6: 11 | G6: Mar | H6: 1120000
A7: Laptop | B7: 16 | G7: Apr | H7: 6125000
A8: Smartphone | B8: 15 | G8: May | H8: 11465000
A9: Sneakers | B9: 7 | G9: Jun | H9: 3930000
A10: Television | B10: 11 | G10: Grand Total | H10: 44435000
A11: Wrist Watch | B11: 17
A13: Row Labels | B13: Sum of Amount | G13: Count of Amount | H13: Column Labels
A14: Abuja | B14: 3705000 | G14: Row Labels | H14: Blender | I14: Handbag | J14: Headphones | K14: Laptop | L14: Smartphone | M14: Sneakers | N14: Television | O14: Wrist Watch | P14: Grand Total
A15: Enugu | B15: 3605000 | G15: Abuja | H15: 5 | I15: 1 | J15: 3 | K15: 1 | M15: 2 | N15: 2 | O15: 4 | P15: 18
A16: Ibadan | B16: 5160000 | G16: Enugu | H16: 2 | I16: 1 | L16: 4 | O16: 3 | P16: 10
A17: Kano | B17: 5980000 | G17: Ibadan | H17: 2 | I17: 3 | J17: 1 | K17: 2 | L17: 3 | M17: 1 | N17: 1 | O17: 1 | P17: 14
A18: Lagos | B18: 9910000 | G18: Kano | H18: 2 | I18: 5 | J18: 1 | L18: 3 | M18: 2 | N18: 2 | O18: 6 | P18: 21
A19: Missing | B19: 2605000 | G19: Lagos | H19: 2 | I19: 2 | J19: 5 | K19: 3 | M19: 1 | N19: 4 | O19: 1 | P19: 18
A20: Port Harcourt | B20: 13470000 | G20: Missing | I20: 1 | K20: 2 | L20: 2 | M20: 1 | P20: 6
A21: (blank) | G21: Port Harcourt | H21: 1 | I21: 1 | J21: 1 | K21: 8 | L21: 3 | N21: 2 | O21: 2 | P21: 18
A22: Grand Total | B22: 44435000 | G22: Grand Total | H22: 14 | I22: 14 | J22: 11 | K22: 16 | L22: 15 | M22: 7 | N22: 11 | O22: 17 | P22: 105

Sheet Dashboard
A1: GreenLeaf Retail Nigeria- Sales Dashboard
A3: Jan- Jun 2026 | Dashboard is linked to the Pivot Summary
A5: Total Sales (NGN) | E5: Total Orders | I5: Total Units Sold | M5: Average Order Value (NGN)
A6: =SUM('Cleaned Data'!I2:I106) -> 44435000 | E6: =COUNT('Cleaned Data'!G2:G106) -> 105 | I6: =SUM('Cleaned Data'!G2:G106) -> 340 | M6: =AVERAGE('Cleaned Data'!I2:I106) -> 423190.48
